<?xml version="1.0" ?>
<!-- =================================================================================== -->
<!-- |    This document was autogenerated by xacro from gazebo_model.urdf.xacro        | -->
<!-- |    EDITING THIS FILE BY HAND IS NOT RECOMMENDED                                 | -->
<!-- =================================================================================== -->
<!-- 组合小车底盘与摄像头 -->
<robot name="mycar">
  <!-- 宏:黑色设置 -->
  <material name="black">
    <color rgba="0.0 0.0 0.0 1.0"/>
  </material>
  <material name="gray">
    <color rgba="0.0 0.0 0.0 0.5"/>
  </material>
  <!--Car Body-->
  <link name="base_link">
    <collision>
      <origin rpy="0 0 0" xyz="0 0 0.0"/>
      <geometry>
        <box size="0.8 0.6 0.3"/>
      </geometry>
    </collision>
    <visual>
      <!-- <origin xyz="0.05 0 ${base_collision_height}" rpy="0 0 ${PI/2}"/>   -->
      <origin rpy="0 0 0" xyz="0.05 0 0.0"/>
      <geometry>
        <!-- <mesh filename="package://car_model/meshes/vehicle_body.dae"/> -->
        <box size="0.8 0.6 0.3"/>
      </geometry>
    </visual>
  </link>
  <joint name="inertial_joint" type="fixed">
    <parent link="base_link"/>
    <child link="main_mass"/>
    <origin rpy="0 0 0" xyz="0 0 0"/>
  </joint>
  <link name="main_mass" type="fixed">
    <inertial>
      <origin rpy="0 0 0" xyz="0 0 0"/>
      <mass value="0.5"/>
      <inertia ixx="343" ixy="0.000000" ixz="0.000000" iyy="728" iyz="0.000000" izz="772"/>
    </inertial>
  </link>
  <!--Rear Right Wheel-->
  <joint name="right_back_wheel_joint" type="continuous">
    <parent link="base_link"/>
    <child link="right_back_wheel_link"/>
    <origin rpy="0 0 0" xyz="-0.8 -0.6 0"/>
    <axis xyz="0 1 0"/>
    <dynamics damping="0.1"/>
    <limit effort="100000" velocity="10000"/>
    <joint_properties damping="0.0" friction="0.0"/>
  </joint>
  <link name="right_back_wheel_link">
    <collision>
      <origin rpy="1.5707963417948965 0 0" xyz="0 0 0"/>
      <geometry>
        <cylinder length="0.165" radius="0.3"/>
      </geometry>
    </collision>
    <visual>
      <!-- <origin xyz="0 0 0" rpy="0 0 -${PI/2}"/> -->
      <origin rpy="1.5707963417948965 0 0" xyz="0 0 0"/>
      <geometry>
        <!-- <mesh filename="package://car_model/meshes/wheel.dae"/> -->
        <cylinder length="0.165" radius="0.3"/>
      </geometry>
    </visual>
    <inertial>
      <mass value="20"/>
      <inertia ixx="0.49537499999999995" ixy="0" ixz="0" iyy="0.49537499999999995" iyz="0" izz="0.8999999999999999"/>
    </inertial>
  </link>
  <!--Rear Left Wheel-->
  <joint name="left_back_wheel_joint" type="continuous">
    <parent link="base_link"/>
    <child link="left_back_wheel_link"/>
    <origin rpy="0 0 0" xyz="-0.8 0.6 0"/>
    <axis xyz="0 1 0"/>
    <dynamics damping="0.1"/>
    <limit effort="100000" velocity="10000"/>
    <joint_properties damping="0.0" friction="0.0"/>
  </joint>
  <link name="left_back_wheel_link">
    <collision>
      <origin rpy="1.5707963417948965 0 0" xyz="0 0 0"/>
      <geometry>
        <cylinder length="0.165" radius="0.3"/>
      </geometry>
    </collision>
    <visual>
      <!-- <origin xyz="0 0 0" rpy="0 0 ${PI/2}"/> -->
      <origin rpy="1.5707963417948965 0 0" xyz="0 0 0"/>
      <geometry>
        <!-- <mesh filename="package://car_model/meshes/wheel.dae"/> -->
        <cylinder length="0.165" radius="0.3"/>
      </geometry>
    </visual>
    <inertial>
      <mass value="20"/>
      <inertia ixx="0.49537499999999995" ixy="0" ixz="0" iyy="0.49537499999999995" iyz="0" izz="0.8999999999999999"/>
    </inertial>
  </link>
  <!--Front Right Steering-->
  <joint name="right_front_steering_joint" type="revolute">
    <parent link="base_link"/>
    <child link="right_front_steering_link"/>
    <origin rpy="0 0 0" xyz="0.8 -0.6 0"/>
    <axis xyz="0 0 1"/>
    <limit effort="1000000.0" lower="-0.6" upper="0.6" velocity="10000.0"/>
    <dynamics damping="10.0" friction="0.0"/>
  </joint>
  <link name="right_front_steering_link">
    <visual>
      <origin rpy="1.5707963417948965 0 0" xyz="0 0 0"/>
      <!-- <origin xyz="0 0 0" rpy="0 0 0"/> -->
      <geometry>
        <cylinder length="0.01" radius="0.1"/>
      </geometry>
    </visual>
    <inertial>
      <mass value="5"/>
      <inertia ixx="0.012541666666666668" ixy="0" ixz="0" iyy="0.012541666666666668" iyz="0" izz="0.025"/>
    </inertial>
  </link>
  <!--Front Right Wheel-->
  <joint name="right_front_wheel_joint" type="continuous">
    <parent link="right_front_steering_link"/>
    <child link="right_front_wheel_link"/>
    <origin rpy="0 0 0" xyz="0 0 0"/>
    <axis xyz="0 1 0"/>
    <dynamics damping="0.1"/>
    <limit effort="1000000" velocity="10000"/>
    <joint_properties damping="0.0" friction="0.0"/>
  </joint>
  <link name="right_front_wheel_link">
    <collision>
      <origin rpy="1.5707963417948965 0 0" xyz="0 0 0"/>
      <geometry>
        <cylinder length="0.165" radius="0.3"/>
      </geometry>
    </collision>
    <visual>
      <!-- <origin xyz="0 0 0" rpy="0 0 -${PI/2}"/> -->
      <origin rpy="1.5707963417948965 0 0" xyz="0 0 0"/>
      <geometry>
        <!-- <mesh filename="package://car_model/meshes/wheel.dae"/> -->
        <cylinder length="0.165" radius="0.3"/>
      </geometry>
    </visual>
    <inertial>
      <mass value="20"/>
      <inertia ixx="0.49537499999999995" ixy="0" ixz="0" iyy="0.49537499999999995" iyz="0" izz="0.8999999999999999"/>
    </inertial>
  </link>
  <!--Front Left Steering-->
  <joint name="left_front_steering_joint" type="revolute">
    <parent link="base_link"/>
    <child link="left_front_steering_link"/>
    <origin rpy="0 0 0" xyz="0.8 0.6 0"/>
    <axis xyz="0 0 1"/>
    <limit effort="1000000.0" lower="-0.6" upper="0.6" velocity="10000.0"/>
    <dynamics damping="10.0" friction="0.0"/>
  </joint>
  <link name="left_front_steering_link">
    <visual>
      <origin rpy="1.5707963417948965 0 0" xyz="0 0 0"/>
      <geometry>
        <cylinder length="0.01" radius="0.1"/>
      </geometry>
    </visual>
    <inertial>
      <mass value="5"/>
      <inertia ixx="0.012541666666666668" ixy="0" ixz="0" iyy="0.012541666666666668" iyz="0" izz="0.025"/>
    </inertial>
  </link>
  <!--Front Left Wheel-->
  <joint name="left_front_wheel_joint" type="continuous">
    <parent link="left_front_steering_link"/>
    <child link="left_front_wheel_link"/>
    <origin rpy="0 0 0" xyz="0 0 0"/>
    <axis xyz="0 1 0"/>
    <dynamics damping="0.1"/>
    <limit effort="1000000" velocity="10000"/>
    <joint_properties damping="0.0" friction="0.0"/>
  </joint>
  <link name="left_front_wheel_link">
    <collision>
      <origin rpy="1.5707963417948965 0 0" xyz="0 0 0"/>
      <geometry>
        <cylinder length="0.165" radius="0.3"/>
      </geometry>
    </collision>
    <visual>
      <!-- <origin xyz="0 0 0" rpy="0 0 ${PI/2}"/> -->
      <origin rpy="1.5707963417948965 0 0" xyz="0 0 0"/>
      <geometry>
        <!-- <mesh filename="package://car_model/meshes/wheel.dae"/> -->
        <cylinder length="0.165" radius="0.3"/>
      </geometry>
    </visual>
    <inertial>
      <mass value="20"/>
      <inertia ixx="0.49537499999999995" ixy="0" ixz="0" iyy="0.49537499999999995" iyz="0" izz="0.8999999999999999"/>
    </inertial>
  </link>
  <transmission name="right_front_steering_transmission" type="SimpleTransmission">
    <type>transmission_interface/SimpleTransmission</type>
    <joint name="right_front_steering_joint">
      <hardwareInterface>hardware_interface/EffortJointInterface</hardwareInterface>
    </joint>
    <actuator name="right_front_steering_motor">
      <hardwareInterface>hardware_interface/EffortJointInterface</hardwareInterface>
      <mechanicalReduction>1</mechanicalReduction>
    </actuator>
  </transmission>
  <transmission name="left_front_steering_transmission" type="SimpleTransmission">
    <type>transmission_interface/SimpleTransmission</type>
    <joint name="left_front_steering_joint">
      <hardwareInterface>hardware_interface/EffortJointInterface</hardwareInterface>
    </joint>
    <actuator name="left_front_steering_motor">
      <hardwareInterface>hardware_interface/EffortJointInterface</hardwareInterface>
      <mechanicalReduction>1</mechanicalReduction>
    </actuator>
  </transmission>
  <transmission name="left_back_wheel_transmission" type="SimpleTransmission">
    <type>transmission_interface/SimpleTransmission</type>
    <joint name="left_back_wheel_joint">
      <hardwareInterface>hardware_interface/VelocityJointInterface</hardwareInterface>
    </joint>
    <actuator name="left_back_wheel_motor">
      <hardwareInterface>hardware_interface/VelocityJointInterface</hardwareInterface>
      <mechanicalReduction>1</mechanicalReduction>
    </actuator>
  </transmission>
  <transmission name="right_back_wheel_transmission" type="SimpleTransmission">
    <type>transmission_interface/SimpleTransmission</type>
    <joint name="right_back_wheel_joint">
      <hardwareInterface>hardware_interface/VelocityJointInterface</hardwareInterface>
    </joint>
    <actuator name="right_back_wheel_motor">
      <hardwareInterface>hardware_interface/VelocityJointInterface</hardwareInterface>
      <mechanicalReduction>1</mechanicalReduction>
    </actuator>
  </transmission>
  <!-- 控制器 -->
  <!-- <gazebo reference="left_front_wheel"> -->
  <gazebo reference="left_front_wheel_joint">
    <mu1 value="2.0"/>
    <mu2 value="2.0"/>
    <kp value="10000000.0"/>
    <kd value="1.0"/>
    <fdir1 value="0 0 1"/>
  </gazebo>
  <!-- <gazebo reference="right_front_wheel"> -->
  <gazebo reference="right_front_wheel_joint">
    <mu1 value="2.0"/>
    <mu2 value="2.0"/>
    <kp value="10000000.0"/>
    <kd value="1.0"/>
    <fdir1 value="0 0 1"/>
    <kd>1</kd>
  </gazebo>
  <!-- <gazebo reference="base_link">
        <mu1 value="0.0"/>
        <mu2 value="0.0"/>
        <kp  value="10000000.0" />
        <kd  value="1.0" />
       
    </gazebo> -->
  <!-- <gazebo reference="left_steering_hinge"> -->
  <!-- <gazebo reference="left_front_wheel_axle2left_front_wheel_joint">
        <mu1 value="2.0"/>
        <mu2 value="2.0"/>
        <kp  value="10000000.0" />
        <kd  value="1.0" />
        <fdir1 value="1 0 0"/>
        <material>Gazebo/Grey</material>
    </gazebo> -->
  <!-- <gazebo reference="left_rear_wheel"> -->
  <gazebo reference="left_back_wheel_joint">
    <mu1 value="2.0"/>
    <mu2 value="2.0"/>
    <kp value="10000000.0"/>
    <kd value="1.0"/>
    <fdir1 value="1 0 0"/>
  </gazebo>
  <!-- <gazebo reference="right_steering_hinge"> -->
  <!-- <gazebo reference="right_front_wheel_axle2right_front_wheel_joint">
        <mu1 value="2.0"/>
        <mu2 value="2.0"/>
        <kp  value="10000000.0" />
        <kd  value="1.0" />
        <fdir1 value="1 0 0"/>
        <material>Gazebo/Grey</material>
    </gazebo> -->
  <!-- <gazebo reference="right_rear_wheel"> -->
  <gazebo reference="right_back_wheel_joint">
    <mu1 value="2.0"/>
    <mu2 value="2.0"/>
    <kp value="10000000.0"/>
    <kd value="1.0"/>
    <fdir1 value="1 0 0"/>
  </gazebo>
  <gazebo>
    <plugin filename="libgazebo_ros_control.so" name="gazebo_ros_control">
      <robotNamespace>/mycar</robotNamespace>
      <robotParam>robot_description</robotParam>
      <robotSimType>gazebo_ros_control/DefaultRobotHWSim</robotSimType>
      <legacyModeNS>true</legacyModeNS>
    </plugin>
  </gazebo>
  <gazebo>
    <plugin filename="libgazebo_ros_joint_state_publisher.so" name="joint_state_publisher">
      <jointName>left_front_wheel_joint,
                        right_front_wheel_joint,
                        left_front_steering_joint,
                        right_front_steering_joint,
                        left_back_wheel_joint,
                        right_back_wheel_joint
            </jointName>
      <updateRate>50.0</updateRate>
      <robotNamespace>/mycar</robotNamespace>
      <alwaysOn>true</alwaysOn>
    </plugin>
  </gazebo>
  <!-- 摄像头安装的z坐标:底盘高度 / 2 + 摄像头高度 / 2  -->
  <!-- 摄像头关节以及link -->
  <link name="camera">
    <visual>
      <geometry>
        <box size="0.01 0.025 0.025"/>
      </geometry>
      <origin rpy="0.0 0.0 0.0" xyz="0.0 0.0 0.0"/>
      <material name="black"/>
    </visual>
    <collision>
      <geometry>
        <box size="0.01 0.025 0.025"/>
      </geometry>
      <origin rpy="0.0 0.0 0.0" xyz="0.0 0.0 0.0"/>
    </collision>
    <inertial>
      <mass value="0.01"/>
      <inertia ixx="6.041666666666668e-07" ixy="0" ixz="0" iyy="6.041666666666668e-07" iyz="0" izz="1.041666666666667e-06"/>
    </inertial>
  </link>
  <joint name="camera2base_link" type="fixed">
    <parent link="base_link"/>
    <child link="camera"/>
    <origin xyz="0.08 0.0 0.1625"/>
  </joint>
  <gazebo reference="camera">
    <material>Gazebo/Blue</material>
  </gazebo>
  <!-- 摄像头安装的z坐标:底盘高度 / 2 + 摄像头高度 / 2  -->
  <!-- 摄像头关节以及link -->
  <link name="imu">
    <visual>
      <geometry>
        <box size="0.02 0.03 0.01"/>
      </geometry>
      <origin rpy="0.0 0.0 0.0" xyz="0.0 0.0 0.0"/>
      <material name="black"/>
    </visual>
    <collision>
      <geometry>
        <box size="0.02 0.03 0.01"/>
      </geometry>
      <origin rpy="0.0 0.0 0.0" xyz="0.0 0.0 0.0"/>
    </collision>
    <inertial>
      <mass value="0.01"/>
      <inertia ixx="4.166666666666667e-07" ixy="0" ixz="0" iyy="1.0833333333333333e-06" iyz="0" izz="8.333333333333334e-07"/>
    </inertial>
  </link>
  <joint name="imu2base_link" type="fixed">
    <parent link="base_link"/>
    <child link="imu"/>
    <origin xyz="0.2 0.0 0.155"/>
  </joint>
  <gazebo reference="imu">
    <material>Gazebo/Blue</material>
  </gazebo>
  <!-- 支架安装的z坐标:底盘高度 / 2 + 支架高度 / 2  -->
  <link name="support">
    <visual>
      <geometry>
        <cylinder length="0.15" radius="0.01"/>
      </geometry>
      <origin rpy="0.0 0.0 0.0" xyz="0.0 0.0 0.0"/>
      <material name="red">
        <color rgba="0.8 0.2 0.0 0.8"/>
      </material>
    </visual>
    <collision>
      <geometry>
        <cylinder length="0.15" radius="0.01"/>
      </geometry>
      <origin rpy="0.0 0.0 0.0" xyz="0.0 0.0 0.0"/>
    </collision>
    <inertial>
      <mass value="0.02"/>
      <inertia ixx="3.8e-05" ixy="0" ixz="0" iyy="3.8e-05" iyz="0" izz="1.0000000000000002e-06"/>
    </inertial>
  </link>
  <joint name="support2base_link" type="fixed">
    <parent link="base_link"/>
    <child link="support"/>
    <origin xyz="0.0 0.0 0.22499999999999998"/>
  </joint>
  <gazebo reference="support">
    <material>Gazebo/White</material>
  </gazebo>
  <!-- 雷达安装的z坐标:支架高度 / 2 + 雷达高度 / 2  -->
  <!-- 雷达关节以及link -->
  <link name="laser">
    <visual>
      <geometry>
        <cylinder length="0.05" radius="0.03"/>
      </geometry>
      <origin rpy="0.0 0.0 0.0" xyz="0.0 0.0 0.0"/>
      <material name="black"/>
    </visual>
    <collision>
      <geometry>
        <cylinder length="0.05" radius="0.03"/>
      </geometry>
      <origin rpy="0.0 0.0 0.0" xyz="0.0 0.0 0.0"/>
    </collision>
    <inertial>
      <mass value="0.1"/>
      <inertia ixx="4.333333333333333e-05" ixy="0" ixz="0" iyy="4.333333333333333e-05" iyz="0" izz="4.4999999999999996e-05"/>
    </inertial>
  </link>
  <joint name="laser2support" type="fixed">
    <parent link="support"/>
    <child link="laser"/>
    <origin xyz="0.0 0.0 0.1"/>
  </joint>
  <gazebo reference="laser">
    <material>Gazebo/Black</material>
  </gazebo>
  <!-- <xacro:include filename="gazebo_move.urdf.xacro" /> -->
</robot>

